### Exception Handling ###

numberOne = 5
numberTwo = 1
numberTwo = "1"

try:
    print(numberOne + numberTwo)
    print("No se ha producido un error")
except:
    print("Se ha producido un error")

try:
    print(numberOne + numberTwo)
    print("No se ha producido un error")
except:
    print("Se ha producido un error")
else:
    print("La ejecución continúa correctamente")
finally:
    print("La ejecución continúa")

try:
    print(numberOne + numberTwo)
    print("No se ha producido un error")
except ValueError:
    print("Se ha producido un ValueError")
except TypeError:
    print("Se ha producido un TypeError")

try:
    print(numberOne + numberTwo)
    print("No se ha producido un error")
except ValueError as error:
    print(error)
except Exception as my_random_error_name:
    print(my_random_error_name)